package tools

// Try calls the function and return false in case of error.
func Try(callback func() error) (ok bool) {
	ok = true

	defer func() {
		if r := recover(); r != nil {
			ok = false
		}
	}()

	err := callback()
	if err != nil {
		ok = false
	}

	return
}

// TryWithErrorValue has the same behavior than Try, but also returns value passed to panic.
func TryWithErrorValue(callback func() error) (errorValue any, ok bool) {
	ok = true

	defer func() {
		if r := recover(); r != nil {
			ok = false
			errorValue = r
		}
	}()

	err := callback()
	if err != nil {
		ok = false
		errorValue = err
	}

	return
}

// TryCatch has the same behavior than Try, but calls the catch function in case of error.
func TryCatch(callback func() error, catch func()) {
	if !Try(callback) {
		catch()
	}
}

// TryCatchWithErrorValue has the same behavior than TryWithErrorValue, but calls the catch function in case of error.
func TryCatchWithErrorValue(callback func() error, catch func(any)) {
	if err, ok := TryWithErrorValue(callback); !ok {
		catch(err)
	}
}
